Workbook

Sheet Catalogue
A1: Issuer | B1: Status | C1: Card | D1: Base reward | E1: Accelerated rewards | F1: Reward-point value | G1: Monthly/quarterly/annual caps | H1: Minimum transaction | I1: Excluded categories/MCCs | J1: Excluded merchants | K1: Joining fee | L1: Annual fee | M1: Fee-waiver condition | N1: Forex markup | O1: Lounge benefits | P1: Milestone benefits | Q1: Fuel surcharge waiver | R1: Other benefits | S1: Official source URL | T1: Effective date | U1: Reward source URL | V1: Reward source type | W1: Reward research date | X1: Reward research note
A2: HDFC Bank | B2: Selectable | C2: Millennia Credit Card | D2: 1% CashPoints on eligible spends. | E2: 5% CashPoints on Amazon, Flipkart, Myntra, Tata CLiQ, Swiggy, Zomato, Uber, BookMyShow, Sony LIV and Cult.fit. | F2: 1 CashPoint = ₹1 for statement cashback; ₹0.30 for flights/hotels, airmiles and catalogue redemptions. | G2: Statement cashback redemption max 3,000 CashPoints/month; flights/hotels redemption max 50,000 CashPoints/month. Quarterly milestone at ₹1 lakh eligible spend. | K2: ₹1,000 + applicable taxes | L2: ₹1,000 + applicable taxes | M2: Annual fee waived on ₹1 lakh eligible annual spend. | O2: Quarterly milestone choice can include 1 domestic lounge visit instead of ₹1,000 voucher after ₹1 lakh quarterly spend. | P2: ₹1,000 voucher OR 1 domestic lounge visit on ₹1 lakh spend in a calendar quarter. | Q2: 1% waiver on fuel transactions of ₹400–₹5,000; max ₹250 per statement cycle. | S2: https://www.hdfc.bank.in/credit-cards/millennia-credit-card https://www.hdfc.bank.in/credit-cards | T2: Current product page accessed 2026-09-09
A3: HDFC Bank | B3: Selectable | C3: IndianOil HDFC Bank Credit Card | D3: 1 Fuel Point per ₹150 on eligible other spends, including eligible UPI spends. | E3: 5% Fuel Points on eligible IndianOil fuel, groceries and bill payments. | F3: 1 Fuel Point = 3 IndianOil XTRAREWARDS points; issuer indicates approx. ₹0.96 fuel value and ₹0.20 for catalogue/cashback redemption. | G3: IndianOil fuel: 250 Fuel Points/month for first 6 months, then 150/month; grocery: 100/month; bill payments: 100/month. | S3: https://www.hdfc.bank.in/credit-cards | T3: Current official catalogue accessed 2026-09-09 | U3: https://www.hdfc.bank.in/credit-cards/indianoil-hdfc-bank-credit-card | V3: Official issuer | W3: 2026-09-09 | X3: Second-pass reward/cashback research; populated only from located source material.
A4: HDFC Bank | B4: Selectable | C4: Tata Neu Infinity HDFC Bank Credit Card | D4: 1.5% NeuCoins on eligible non-Tata spends. | E4: 5% NeuCoins on eligible Tata brand spends plus an additional 5% on select Tata Neu transactions; eligible UPI spends earn up to 1.5%. | F4: 1 NeuCoin = ₹1 when redeemed in the Tata Neu ecosystem. | G4: UPI reward component capped at 500 NeuCoins per calendar month. | S4: https://www.hdfc.bank.in/credit-cards | T4: Current official catalogue accessed 2026-09-09 | U4: https://www.hdfc.bank.in/credit-cards/tata-neu-infinity-hdfc-bank-credit-card | V4: Official issuer | W4: 2026-09-09 | X4: Second-pass reward/cashback research; populated only from located source material.
A5: HDFC Bank | B5: Selectable | C5: HDFC Bank MoneyBack+ Credit Card | D5: 2 CashPoints per ₹150 on eligible spends. | E5: 10X CashPoints (20 CashPoints per ₹150) at Amazon, BigBasket, Flipkart, Reliance Smart SuperStore and Swiggy. | G5: Accelerated rewards capped at 2,500 CashPoints/month; total reward accrual capped at 15,000 CashPoints per statement cycle. | I5: Fuel, EMI, rent, government, wallet/gift/prepaid/voucher; education through third-party apps excluded; wallet and EasyEMI excluded. | P5: ₹500 gift voucher at ₹50,000 eligible spend in a calendar quarter; joining/renewal fee payment benefit of 500 CashPoints where applicable. | S5: https://www.hdfc.bank.in/credit-cards/moneyback-plus-credit-card https://www.hdfc.bank.in/credit-cards | T5: Current official product/T&C accessed 2026-09-09
A6: HDFC Bank | B6: Selectable | C6: HDFC Bank Freedom Credit Card | D6: 1 Reward Point per ₹200 on eligible spends. | E6: 10X Reward Points at select partners including BigBasket, BookMyShow, OYO, Swiggy and Uber, subject to current issuer terms. | F6: 1 Reward Point = up to about ₹0.15 for cashback redemption; value varies by redemption option. | S6: https://www.hdfc.bank.in/credit-cards | T6: Current official catalogue accessed 2026-09-09 | U6: https://www.hdfc.bank.in/credit-cards/freedom-credit-card | V6: Official issuer | W6: 2026-09-09 | X6: Second-pass reward/cashback research; populated only from located source material.
A7: HDFC Bank | B7: Selectable | C7: PhonePe HDFC Bank Uno Credit Card | D7: 1% value back on eligible scan-and-pay/UPI spends, subject to card terms. | E7: 2% on eligible PhonePe categories and 1% on select online spends; cashback/reward buckets are separately capped. | F7: 1 Reward Point = ₹1 for cashback redemption; about ₹0.30 on selected SmartBuy redemptions. | G7: Up to 500 Reward Points/month in each of the PhonePe, select-online and scan-and-pay buckets, as applicable. | S7: https://www.hdfc.bank.in/credit-cards | T7: Current official catalogue accessed 2026-09-09 | U7: https://www.hdfc.bank.in/credit-cards/phonepe-hdfc-bank-uno-credit-card | V7: Official issuer | W7: 2026-09-09 | X7: Second-pass reward/cashback research; populated only from located source material.
A8: HDFC Bank | B8: Selectable | C8: PhonePe HDFC Bank Ultimo Credit Card | D8: 1% value back on eligible scan-and-pay/UPI spends. | E8: 10% on eligible PhonePe recharge, utility, bill-payment and travel spends; 5% on select online merchants such as Amazon, Flipkart, Myntra, AJIO, Swiggy, Zomato and Uber. | F8: 1 Reward Point = ₹1 for cashback redemption; about ₹0.30 on selected SmartBuy redemptions. | G8: PhonePe 10% bucket: up to 1,000 Reward Points/month; select-online 5% bucket: up to 500/month; scan-and-pay: up to 500/month. | S8: https://www.hdfc.bank.in/credit-cards | T8: Current official catalogue accessed 2026-09-09 | U8: https://www.hdfc.bank.in/credit-cards/phonepe-hdfc-bank-ultimo-credit-card | V8: Official issuer | W8: 2026-09-09 | X8: Second-pass reward/cashback research; populated only from located source material.
A9: HDFC Bank | B9: Selectable | C9: HDFC Bank Diners Club Black Metal Edition Credit Card | D9: 5 Reward Points per ₹150 on eligible retail spends. | E9: 2X Reward Points on eligible weekend dining and up to 10X through eligible SmartBuy offers. | F9: Up to ₹1/point for eligible flight/hotel redemptions; airline-mile transfer can be up to 1:1; catalogue about ₹0.50 and cashback about ₹0.30 per point. | G9: Accelerated SmartBuy rewards subject to programme caps; quarterly milestone: 10,000 bonus Reward Points on ₹4 lakh eligible quarterly spend. | S9: https://www.hdfc.bank.in/credit-cards | T9: Current official catalogue accessed 2026-09-09 | U9: https://v.hdfc.bank.in/htdocs/amp/personal/pay/cards/credit-cards/diners-club-black-metal-edition.html | V9: Official issuer | W9: 2026-09-09 | X9: Second-pass reward/cashback research; populated only from located source material.
A10: HDFC Bank | B10: Selectable | C10: HDFC Bank PIXEL Play Credit Card | D10: 1% cashback/reward value on eligible spends. | E10: 5% on chosen benefit packs, 5% through eligible SmartBuy spends, 3% on eligible e-commerce and 1% on eligible UPI spends. | G10: Issuer T&C provides separate monthly caps, commonly up to ₹500 in each accelerated bucket. | K10: ₹500 (published card fee; fee-waiver conditions may apply). | L10: ₹500 | M10: Joining fee waiver at ₹20,000 eligible spend in first 90 days; renewal fee waiver at ₹1 lakh annual spend. | S10: https://www.hdfc.bank.in/credit-cards | T10: Current HDFC PIXEL MITC/product material accessed 2026-09-09 | U10: https://www.hdfc.bank.in/content/dam/hdfcbankpws/in/en/personal-banking/discover-products/cards/credit-cards/pixel-play-credit-card/terms-and-conditions-pixel-play-credit-card-16122025.pdf | V10: Official issuer | W10: 2026-09-09 | X10: Second-pass reward/cashback research; populated only from located source material.
A11: HDFC Bank | B11: Selectable | C11: HDFC Bank PIXEL Go Credit Card | D11: 1% cashback/reward value on eligible spends. | E11: 5% on eligible SmartBuy transactions and 1% on eligible UPI transactions. | K11: ₹250 (published card fee; fee-waiver conditions may apply). | L11: ₹250 | M11: Joining fee waiver at ₹10,000 eligible spend in first 90 days. | S11: https://www.hdfc.bank.in/credit-cards | T11: Current HDFC PIXEL MITC/product material accessed 2026-09-09 | U11: https://www.hdfc.bank.in/credit-cards/pixel-go-credit-card | V11: Official issuer | W11: 2026-09-09 | X11: Second-pass reward/cashback research; populated only from located source material.
A12: HDFC Bank | B12: Selectable | C12: HDFC Bank UPI RuPay Credit Card | D12: 1% CashPoints on eligible spends. | E12: 3% CashPoints on eligible grocery, supermarket, dining and PayZapp spends; 2% on eligible utility spends. | F12: 1 CashPoint = ₹0.25 for cashback redemption. | G12: Accelerated CashPoints capped at 500 points per category per calendar month. | H12: ₹100 minimum eligible transaction for reward accrual, subject to current terms. | S12: https://www.hdfc.bank.in/credit-cards | T12: Current official catalogue accessed 2026-09-09 | U12: https://www.hdfc.bank.in/credit-cards/hdfc-bank-upi-rupay-credit-card | V12: Official issuer | W12: 2026-09-09 | X12: Second-pass reward/cashback research; populated only from located source material.
A13: HDFC Bank | B13: Selectable | C13: HDFC Bank Regalia Gold Credit Card | D13: 4 Reward Points per ₹150 on eligible retail spends. | E13: Up to 20 Reward Points per ₹150 at selected accelerated partners/SmartBuy offers. | F13: Typical values: up to ₹0.65/point on selected catalogue rewards, about ₹0.50 for eligible flight/hotel redemptions, and about ₹0.20 as statement cashback. | N13: 2% foreign-currency markup, per current official card material. | O13: Up to 12 domestic lounge visits/year; Priority Pass benefit includes up to 6 international lounge visits/year, subject to current programme terms. | P13: ₹5,000 flight voucher at ₹5 lakh annual spend and an additional ₹5,000 flight voucher at ₹7.5 lakh annual spend. | S13: https://www.hdfc.bank.in/credit-cards/regalia-gold-credit-card https://www.hdfc.bank.in/credit-cards | T13: Current official card material accessed 2026-09-09 | U13: https://www.hdfc.bank.in/blogs/regalia-gold-credit-card/redeem-regalia-gold-credit-card-reward-points | V13: Official issuer | W13: 2026-09-09 | X13: Second-pass reward/cashback research; populated only from located source material.
A14: HDFC Bank | B14: Selectable | C14: HDFC Bank Diners Club Privilege Credit Card | D14: Regular Reward Points on eligible spends; card-specific base rate is published on the product page. | E14: 5X rewards on eligible Swiggy and Zomato spends (20 RP/₹150 in the cited card T&C). | G14: Incremental accelerated rewards capped at 2,500 RP/month. | H14: ₹150 for the cited accelerated-reward calculation. | I14: Wallet spends excluded from the cited accelerated offer; merchant/category qualification may use MCC 5411, 5499, 5811, 5812, 5814 or issuer merchant identifiers. | S14: https://www.hdfc.bank.in/credit-cards/diners-club-privilege-credit-card https://www.hdfc.bank.in/credit-cards | T14: Current official product/T&C accessed 2026-09-09
A15: HDFC Bank | B15: Selectable | C15: Tata Neu Plus HDFC Bank Credit Card | D15: 1% NeuCoins on eligible non-Tata spends. | E15: 2% NeuCoins on eligible Tata brand spends plus additional rewards on selected Tata Neu transactions; eligible UPI spends earn up to 1%. | F15: 1 NeuCoin = ₹1 in the Tata Neu ecosystem. | L15: ₹499 + applicable taxes (published HDFC MITC value). | M15: Annual fee waiver at ₹1 lakh eligible annual spend. | S15: https://www.hdfc.bank.in/credit-cards | T15: HDFC MITC updated 2025-07-14; catalogue accessed 2026-09-09 | U15: https://www.hdfc.bank.in/credit-cards/tata-neu-plus-hdfc-bank-credit-card | V15: Official issuer | W15: 2026-09-09 | X15: Second-pass reward/cashback research; populated only from located source material.
A16: HDFC Bank | B16: Selectable | C16: Swiggy HDFC Bank Credit Card | D16: 1% cashback on other eligible spends. | E16: 10% cashback on eligible Swiggy spends and 5% on specified online categories/merchants. | G16: Current issuer page states category-wise statement-cycle caps, including up to ₹1,500 for Swiggy, up to ₹1,500 for the 5% online bucket and up to ₹500 for the 1% bucket. | L16: ₹500 + applicable taxes. | M16: Annual fee waiver at ₹2 lakh eligible annual spend. | S16: https://www.hdfc.bank.in/credit-cards | T16: HDFC MITC updated 2025-07-14; catalogue accessed 2026-09-09 | U16: https://www.hdfc.bank.in/credit-cards/swiggy-hdfc-bank-credit-card | V16: Official issuer | W16: 2026-09-09 | X16: Second-pass reward/cashback research; populated only from located source material.
A17: HDFC Bank | B17: Selectable | C17: Swiggy Ornge HDFC Bank Credit Card | D17: 1% cashback on eligible other spends. | E17: 5% cashback on eligible Swiggy spends and 5% on selected online merchants/categories. | S17: https://www.hdfc.bank.in/credit-cards | T17: Current official catalogue accessed 2026-09-09 | U17: https://www.hdfc.bank.in/credit-cards/swiggy-ornge-hdfc-bank-credit-card | V17: Official issuer | W17: 2026-09-09 | X17: Second-pass reward/cashback research; populated only from located source material.
A18: HDFC Bank | B18: Selectable | C18: Swiggy BLCK HDFC Bank Credit Card | D18: 1% cashback on eligible other spends. | E18: 10% cashback on eligible Swiggy spends and 5% on selected online merchants/categories. | S18: https://www.hdfc.bank.in/credit-cards | T18: Current official catalogue accessed 2026-09-09 | U18: https://www.hdfc.bank.in/credit-cards/swiggy-blck-hdfc-bank-credit-card | V18: Official issuer | W18: 2026-09-09 | X18: Second-pass reward/cashback research; populated only from located source material.
A19: HDFC Bank | B19: Selectable | C19: Marriott Bonvoy HDFC Bank Credit Card | D19: 2 Marriott Bonvoy points per ₹150 on eligible spends. | E19: 8 Marriott Bonvoy points per ₹150 at participating Marriott hotels; 4 points per ₹150 on eligible travel, dining and entertainment categories. | L19: ₹3,000 + applicable taxes. | M19: No annual-fee waiver stated in cited HDFC MITC. | S19: https://www.hdfc.bank.in/credit-cards | T19: HDFC MITC updated 2025-07-14; catalogue accessed 2026-09-09 | U19: https://www.hdfc.bank.in/credit-cards/marriott-bonvoy-credit-card | V19: Official issuer | W19: 2026-09-09 | X19: Second-pass reward/cashback research; populated only from located source material.
A20: HDFC Bank | B20: Selectable | C20: IRCTC HDFC Bank Credit Card | D20: 1 Reward Point per ₹100 on eligible spends. | E20: 5 Reward Points per ₹100 on eligible IRCTC train-ticket spends plus eligible SmartBuy benefits. | F20: 1 Reward Point = ₹1 when used for eligible train-ticket redemption through the specified HDFC/IRCTC channel. | G20: Accelerated IRCTC rewards capped at 1,000 Reward Points/month and 12,000/year under issuer terms. | S20: https://www.hdfc.bank.in/credit-cards | T20: Current official catalogue accessed 2026-09-09 | U20: https://www.hdfc.bank.in/credit-cards/irctc-credit-card | V20: Official issuer | W20: 2026-09-09 | X20: Second-pass reward/cashback research; populated only from located source material.
A21: HDFC Bank | B21: Selectable | C21: HDFC Bank INFINIA Metal Edition Credit Card | D21: 5 Reward Points per ₹150 on eligible retail spends. | E21: Up to 10X Reward Points on eligible SmartBuy spends. | F21: Up to ₹1/point for eligible flight/hotel redemption; airline-mile transfer can be up to 1:1; catalogue about ₹0.50 and cashback about ₹0.30 per point. | S21: https://www.hdfc.bank.in/credit-cards | T21: Current official catalogue accessed 2026-09-09 | U21: https://www.hdfc.bank.in/credit-cards/infinia-credit-card | V21: Official issuer | W21: 2026-09-09 | X21: Second-pass reward/cashback research; populated only from located source material.
A22: ICICI Bank | B22: Selectable | C22: Amazon Pay ICICI Bank Credit Card | D22: 1% cashback on eligible payments outside Amazon/partner acceleration. | E22: 5% cashback on Amazon for eligible Prime members; 3% for eligible non-Prime Amazon purchases; 2% on 100+ eligible Amazon Pay partner merchants; some Amazon digital/gift-card categories earn 2%. | F22: N/A – cashback is credited as Amazon Pay balance/cashback per programme terms. | G22: No general cashback cap stated on the official card page; cashback does not expire under the programme. | I22: No cashback on rent or fuel; specified gold/silver/precious-metal/tax categories and Amazon EMI are excluded under current programme terms. | K22: Nil | L22: Nil | Q22: 1% fuel surcharge waiver subject to issuer terms. | S22: https://www.icicibank.com/personal-banking/cards/credit-card | T22: Current official product/FAQ accessed 2026-09-09
A23: ICICI Bank | B23: Selectable | C23: ICICI Bank Coral Credit Card | D23: 2 Reward Points per ₹100 on eligible retail spends; 1 Reward Point per ₹100 on utilities and insurance. | K23: ₹500 + GST | L23: ₹500 + GST | M23: Annual fee waived on eligible annual spend above ₹1.5 lakh. | O23: Domestic lounge access subject to ₹75,000 spend in the preceding calendar quarter; 1 railway lounge visit/quarter under current programme terms. | Q23: 1% waiver on eligible HPCL transactions of ₹400–₹4,000 at ICICI merchant terminals. | S23: https://www.icicibank.com/personal-banking/cards/credit-card | T23: Current official product material accessed 2026-09-09 | U23: https://www.icici.bank.in/personal-banking/cards/credit-card/coral-credit-card | V23: Official issuer | W23: 2026-09-09 | X23: Second-pass reward/cashback research; populated only from located source material.
A24: ICICI Bank | B24: Selectable | C24: ICICI Bank Sapphiro Credit Card | D24: 2 Reward Points per ₹100 on eligible domestic spends and 4 per ₹100 on eligible international spends; 1 per ₹100 on utilities/insurance. | K24: ₹6,500 + GST | L24: ₹3,500 + GST | M24: Annual fee waived on eligible annual spend above ₹6 lakh. | O24: Domestic lounge access subject to ₹75,000 previous-quarter spend; current card material also provides international lounge access. Duo variants may carry separate network entitlements. | R24: Golf entitlement linked to previous-month spend under current programme. | S24: https://www.icicibank.com/personal-banking/cards/credit-card | T24: Current official product material accessed 2026-09-09 | U24: https://www.icici.bank.in/personal-banking/cards/credit-card | V24: Official issuer | W24: 2026-09-09 | X24: Second-pass reward/cashback research; populated only from located source material.
A25: ICICI Bank | B25: Selectable | C25: Times Black ICICI Bank Credit Card | D25: Reward earn equivalent to about 2% on eligible domestic spends and 2.5% on eligible international spends. | E25: Up to 6X on eligible flight/voucher bookings and up to 12X on hotels through eligible iShop channels. | F25: 1 Reward Point can be worth up to ₹1 on selected products/vouchers; statement cashback value is lower (about ₹0.40/point). | N25: 1.49% | S25: https://www.icicibank.com/personal-banking/cards/credit-card | T25: Current official product material accessed 2026-09-09 | U25: https://www.icici.bank.in/personal-banking/cards/credit-card/times-black-icici-credit-card | V25: Official issuer | W25: 2026-09-09 | X25: Second-pass reward/cashback research; populated only from located source material.
A26: ICICI Bank | B26: Selectable | C26: ICICI Bank Emeralde Credit Card | D26: 4 Reward Points per ₹100 on eligible domestic and international retail spends; lower earn on utilities/insurance. | Q26: 1% fuel surcharge waiver on eligible fuel transactions up to ₹4,000, subject to current terms. | S26: https://www.icicibank.com/personal-banking/cards/credit-card | T26: Current official product material accessed 2026-09-09 | U26: https://www.icici.bank.in/personal-banking/cards/credit-card | V26: Official issuer | W26: 2026-09-09 | X26: Second-pass reward/cashback research; populated only from located source material.
A27: ICICI Bank | B27: Selectable | C27: ICICI Bank Rubyx Credit Card | D27: 2 Reward Points per ₹100 on eligible domestic spends and 4 per ₹100 on eligible international spends; 1 per ₹100 on utilities/insurance. | S27: https://www.icicibank.com/personal-banking/cards/credit-card | T27: Current official catalogue accessed 2026-09-09 | U27: https://www.icici.bank.in/personal-banking/cards/credit-card | V27: Official issuer | W27: 2026-09-09 | X27: Second-pass reward/cashback research; populated only from located source material.
A28: ICICI Bank | B28: Selectable | C28: ICICI Bank Platinum Chip Credit Card | D28: 2 Reward Points per ₹100 on eligible retail spends; 1 Reward Point per ₹100 on utilities and insurance. | K28: Nil | L28: Nil | Q28: Fuel-surcharge waiver available subject to current ICICI terms. | S28: https://www.icicibank.com/personal-banking/cards/credit-card | T28: Current official product page accessed 2026-09-09 | U28: https://www.icici.bank.in/personal-banking/cards/credit-card/platinum-chip-credit-card | V28: Official issuer | W28: 2026-09-09 | X28: Second-pass reward/cashback research; populated only from located source material.
A29: ICICI Bank | B29: Selectable | C29: Adani One ICICI Bank Signature Credit Card | D29: 1.5% Adani Reward Points/value on eligible domestic spends and 2% on eligible international spends. | E29: Up to 7% reward value on eligible Adani One ecosystem spends. | K29: ₹5,000 + GST | L29: ₹5,000 + GST | O29: Airport/co-brand benefits include lounge/airport-service entitlements as published for the card. | P29: Welcome flight voucher benefit linked to fee payment and ₹25,000 eligible spend within 60 days, subject to current terms. | R29: Includes Adani airport services such as Pranaam/Porter/parking entitlements under current programme terms. | S29: https://www.icicibank.com/personal-banking/cards/credit-card | T29: Current official co-brand page accessed 2026-09-09 | U29: https://www.icici.bank.in/personal-banking/cards/credit-card/adani-icici-credit-card/signature-credit-card | V29: Official issuer | W29: 2026-09-09 | X29: Second-pass reward/cashback research; populated only from located source material.
A30: ICICI Bank | B30: Selectable | C30: Adani One ICICI Bank Platinum Credit Card | D30: 1% Adani Reward Points/value on eligible domestic spends and 1.5% on eligible international spends. | E30: Up to 3% reward value on eligible Adani One ecosystem spends. | K30: ₹750 + GST | L30: ₹750 + GST | R30: Current official co-brand material includes domestic lounge and Adani airport-service benefits such as Porter/premium parking. | S30: https://www.icicibank.com/personal-banking/cards/credit-card | T30: Current official co-brand page accessed 2026-09-09 | U30: https://www.icici.bank.in/personal-banking/cards/credit-card/adani-icici-credit-card/platinum-credit-card | V30: Official issuer | W30: 2026-09-09 | X30: Second-pass reward/cashback research; populated only from located source material.
A31: ICICI Bank | B31: Selectable | C31: MakeMyTrip ICICI Bank Credit Card | E31: Up to 6% myCash on eligible MakeMyTrip transactions, subject to category/booking terms. | N31: 0.99% | O31: Official card material advertises 8 domestic and 1 international lounge visit/year, subject to conditions. | R31: MakeMyTrip joining/annual-voucher benefits and MMTBLACK Gold-related travel benefits under current terms. | S31: https://www.icicibank.com/personal-banking/cards/credit-card | T31: Current official product page accessed 2026-09-09
A32: ICICI Bank | B32: Selectable | C32: Emirates ICICI Bank Emeralde Credit Card | D32: 2 Emirates Skywards Miles per ₹100 on eligible domestic and international spends. | S32: https://www.icicibank.com/personal-banking/cards/credit-card | T32: Current official catalogue accessed 2026-09-09 | U32: https://www.icici.bank.in/personal-banking/cards/credit-card/emirates-skywards/emirates-emeralde | V32: Official issuer | W32: 2026-09-09 | X32: Second-pass reward/cashback research; populated only from located source material.
A33: ICICI Bank | B33: Selectable | C33: Emirates ICICI Bank Sapphiro Credit Card | D33: 1.5 Emirates Skywards Miles per ₹100 on eligible spends. | S33: https://www.icicibank.com/personal-banking/cards/credit-card | T33: Current official catalogue accessed 2026-09-09 | U33: https://www.icici.bank.in/personal-banking/cards/credit-card | V33: Official issuer | W33: 2026-09-09 | X33: Second-pass reward/cashback research; populated only from located source material.
A34: ICICI Bank | B34: Selectable | C34: HPCL Super Saver ICICI Bank Credit Card | E34: 5% value proposition on selected categories; 20 RP/₹100 on eligible accelerated spends, with published category caps. | G34: Accelerated reward value capped at ₹100/month for specified categories; HPCL cashback component capped at ₹200/month under current programme. | K34: ₹500 + GST | L34: ₹500 + GST | Q34: Up to 5% fuel savings proposition: 4% cashback component (cap applies) plus 1% surcharge waiver; additional HP Pay benefits may apply. | S34: https://www.icicibank.com/personal-banking/cards/credit-card | T34: Current official card page accessed 2026-09-09
A35: ICICI Bank | B35: Selectable | C35: HPCL ICICI Bank Coral Credit Card | D35: 2 Reward Points per ₹100 on eligible retail spends; 1 per ₹100 on utilities/insurance. | E35: 2.5% cashback/value back on eligible HPCL fuel spends, subject to monthly cap and conditions. | G35: HPCL fuel cashback/value-back cap commonly stated as ₹100/month on the issuer product proposition. | K35: ₹199 + GST | L35: ₹199 + GST | Q35: HPCL value proposition includes 2.5% cashback (max ₹100/month) plus 1% fuel surcharge waiver on eligible ICICI POS transactions. | R35: BookMyShow discount published for this card, subject to monthly/transaction limits. | S35: https://www.icicibank.com/personal-banking/cards/credit-card | T35: Current official card page accessed 2026-09-09 | U35: https://www.icici.bank.in/personal-banking/cards/credit-card/hpcl-coral-credit-card | V35: Official issuer | W35: 2026-09-09 | X35: Second-pass reward/cashback research; populated only from located source material.
A36: ICICI Bank | B36: Selectable | C36: ICICI Bank Expressions Credit Card | D36: 3 Reward Points per ₹100 on eligible general retail spends; 1 per ₹100 on utilities/insurance. | S36: https://www.icicibank.com/personal-banking/cards/credit-card | T36: Current official catalogue accessed 2026-09-09 | U36: https://www.icici.bank.in/personal-banking/cards/credit-card/expressions-card | V36: Official issuer | W36: 2026-09-09 | X36: Second-pass reward/cashback research; populated only from located source material.
A37: ICICI Bank | B37: Selectable | C37: ICICI Bank Emeralde Private Metal Credit Card | D37: 6 Reward Points per ₹200 on eligible retail spends. | K37: ₹12,499 + GST | L37: ₹12,499 + GST | O37: Unlimited domestic and international lounge access under current programme terms. | Q37: 1% fuel surcharge waiver on eligible fuel transactions up to ₹4,000. | R37: Premium Taj/EazyDiner/golf benefits under current card programme. | S37: https://www.icicibank.com/personal-banking/cards/credit-card | T37: Current official product page accessed 2026-09-09 | U37: https://www.icici.bank.in/personal-banking/cards/credit-card/emeralde-private-metal-credit-card | V37: Official issuer | W37: 2026-09-09 | X37: Second-pass reward/cashback research; populated only from located source material.
A38: ICICI Bank | B38: Discontinued | C38: Emirates Skywards ICICI Bank Rubyx Credit Card | D38: 1 Emirates Skywards Mile per ₹100 on eligible spends under the legacy card proposition. | L38: Published as non-waivable in legacy official material. | S38: https://www.icicibank.com/personal-banking/cards/credit-card | T38: Legacy official product material; discontinued | U38: https://www.icici.bank.in/personal-banking/cards/credit-card | V38: Official issuer | W38: 2026-09-09 | X38: Discontinued card; earn rate recovered from issuer legacy/product material.
A39: ICICI Bank | B39: Discontinued | C39: MakeMyTrip ICICI Bank Signature Credit Card | D39: 1.25 MyCash per ₹200 on eligible domestic spends outside MakeMyTrip; 1.5 MyCash per ₹200 on eligible international spends. | E39: 2 MyCash per ₹200 on eligible MakeMyTrip flight bookings and 4 MyCash per ₹200 on eligible MakeMyTrip hotel/holiday bookings. | F39: 1 MyCash = ₹1 when redeemed under the MakeMyTrip programme, subject to programme rules. | S39: https://www.icicibank.com/personal-banking/cards/credit-card | T39: Legacy official product material; discontinued | U39: https://www.icici.bank.in/personal-banking/cards/credit-card | V39: Official issuer | W39: 2026-09-09 | X39: Discontinued legacy MakeMyTrip variant; rates recovered from issuer legacy terms.
A40: ICICI Bank | B40: Discontinued | C40: MakeMyTrip ICICI Bank Platinum Credit Card | D40: 1 MyCash per ₹200 on eligible domestic spends outside MakeMyTrip; 1.25 MyCash per ₹200 on eligible international spends. | E40: 2 MyCash per ₹200 on eligible MakeMyTrip flight bookings and 3 MyCash per ₹200 on eligible MakeMyTrip hotel/holiday bookings. | F40: 1 MyCash = ₹1 under the MakeMyTrip programme, subject to programme rules. | S40: https://www.icicibank.com/personal-banking/cards/credit-card | T40: Legacy official product material; discontinued | U40: https://www.icici.bank.in/personal-banking/cards/credit-card/makemytrip/platinum-credit-card/tnc-for-governing-mmt-platinum-credit-card | V40: Official issuer | W40: 2026-09-09 | X40: Second-pass reward/cashback research; populated only from located source material.
...

Sheet README
A1: LedgerKit Credit Card Catalogue Research
A3: Scope
A4: 295 cards across 16 issuers: 249 selectable and 46 discontinued. All rows from the supplied catalogue are retained.
A6: Methodology
A7: • Primary-source first: issuer product pages, current MITC/KFS/schedules, and official cardmember agreements were prioritized.
A8: • Blank cells are intentional. They mean a sufficiently clear official value was not located in the research pass; blanks should not be interpreted as zero, no benefit, or no exclusion.
A9: • For discontinued cards, legacy facts are populated only when official legacy/current-servicing material was found. Historical cards are retained even when their old product page is no longer public.
A10: • Issuer-wide rules are used only where the issuer document explicitly applies them to the card/variant. Co-brand-specific rules are not inferred from generic issuer rules.
A11: • Effective date records a document date when explicit; otherwise it records the official page access date (9 September 2026).
A12: • Fees shown generally exclude GST unless the text explicitly says otherwise. Benefit availability can depend on network variant, spend qualification, account relationship, and issuer changes.

Sheet Coverage
A1: Catalogue Integrity & Coverage
A3: Metric | B3: Value
A4: Total cards | B4: =COUNTA(Catalogue!C2:C296)
A5: Selectable | B5: =COUNTIF(Catalogue!B2:B296,"Selectable")
A6: Discontinued | B6: =COUNTIF(Catalogue!B2:B296,"Discontinued")
A7: Issuers | B7: =COUNTA(A11:A26)
A10: Issuer | B10: Total | C10: Selectable | D10: Discontinued
A11: HDFC Bank | B11: =COUNTIF(Catalogue!$A$2:$A$296,A11) | C11: =COUNTIFS(Catalogue!$A$2:$A$296,A11,Catalogue!$B$2:$B$296,"Selectable") | D11: =COUNTIFS(Catalogue!$A$2:$A$296,A11,Catalogue!$B$2:$B$296,"Discontinued")
A12: ICICI Bank | B12: =COUNTIF(Catalogue!$A$2:$A$296,A12) | C12: =COUNTIFS(Catalogue!$A$2:$A$296,A12,Catalogue!$B$2:$B$296,"Selectable") | D12: =COUNTIFS(Catalogue!$A$2:$A$296,A12,Catalogue!$B$2:$B$296,"Discontinued")
A13: Axis Bank | B13: =COUNTIF(Catalogue!$A$2:$A$296,A13) | C13: =COUNTIFS(Catalogue!$A$2:$A$296,A13,Catalogue!$B$2:$B$296,"Selectable") | D13: =COUNTIFS(Catalogue!$A$2:$A$296,A13,Catalogue!$B$2:$B$296,"Discontinued")
A14: SBI Card | B14: =COUNTIF(Catalogue!$A$2:$A$296,A14) | C14: =COUNTIFS(Catalogue!$A$2:$A$296,A14,Catalogue!$B$2:$B$296,"Selectable") | D14: =COUNTIFS(Catalogue!$A$2:$A$296,A14,Catalogue!$B$2:$B$296,"Discontinued")
A15: Kotak Mahindra Bank | B15: =COUNTIF(Catalogue!$A$2:$A$296,A15) | C15: =COUNTIFS(Catalogue!$A$2:$A$296,A15,Catalogue!$B$2:$B$296,"Selectable") | D15: =COUNTIFS(Catalogue!$A$2:$A$296,A15,Catalogue!$B$2:$B$296,"Discontinued")
A16: IDFC FIRST Bank | B16: =COUNTIF(Catalogue!$A$2:$A$296,A16) | C16: =COUNTIFS(Catalogue!$A$2:$A$296,A16,Catalogue!$B$2:$B$296,"Selectable") | D16: =COUNTIFS(Catalogue!$A$2:$A$296,A16,Catalogue!$B$2:$B$296,"Discontinued")
A17: IndusInd Bank | B17: =COUNTIF(Catalogue!$A$2:$A$296,A17) | C17: =COUNTIFS(Catalogue!$A$2:$A$296,A17,Catalogue!$B$2:$B$296,"Selectable") | D17: =COUNTIFS(Catalogue!$A$2:$A$296,A17,Catalogue!$B$2:$B$296,"Discontinued")
A18: AU Small Finance Bank | B18: =COUNTIF(Catalogue!$A$2:$A$296,A18) | C18: =COUNTIFS(Catalogue!$A$2:$A$296,A18,Catalogue!$B$2:$B$296,"Selectable") | D18: =COUNTIFS(Catalogue!$A$2:$A$296,A18,Catalogue!$B$2:$B$296,"Discontinued")
A19: YES BANK | B19: =COUNTIF(Catalogue!$A$2:$A$296,A19) | C19: =COUNTIFS(Catalogue!$A$2:$A$296,A19,Catalogue!$B$2:$B$296,"Selectable") | D19: =COUNTIFS(Catalogue!$A$2:$A$296,A19,Catalogue!$B$2:$B$296,"Discontinued")
A20: RBL Bank | B20: =COUNTIF(Catalogue!$A$2:$A$296,A20) | C20: =COUNTIFS(Catalogue!$A$2:$A$296,A20,Catalogue!$B$2:$B$296,"Selectable") | D20: =COUNTIFS(Catalogue!$A$2:$A$296,A20,Catalogue!$B$2:$B$296,"Discontinued")
A21: American Express India | B21: =COUNTIF(Catalogue!$A$2:$A$296,A21) | C21: =COUNTIFS(Catalogue!$A$2:$A$296,A21,Catalogue!$B$2:$B$296,"Selectable") | D21: =COUNTIFS(Catalogue!$A$2:$A$296,A21,Catalogue!$B$2:$B$296,"Discontinued")
A22: HSBC India | B22: =COUNTIF(Catalogue!$A$2:$A$296,A22) | C22: =COUNTIFS(Catalogue!$A$2:$A$296,A22,Catalogue!$B$2:$B$296,"Selectable") | D22: =COUNTIFS(Catalogue!$A$2:$A$296,A22,Catalogue!$B$2:$B$296,"Discontinued")
... A26: Federal Bank | B26: =COUNTIF(Catalogue!$A$2:$A$296,A26) | C26: =COUNTIFS(Catalogue!$A$2:$A$296,A26,Catalogue!$B$2:$B$296,"Selectable") | D26: =COUNTIFS(Catalogue!$A$2:$A$296,A26,Catalogue!$B$2:$B$296,"Discontinued")
A29: Requested field | B29: Nonblank rows | C29: Coverage %
A30: Base reward | B30: =COUNTA(Catalogue!D2:D296) | C30: =B30/$B$4
A31: Accelerated rewards | B31: =COUNTA(Catalogue!E2:E296) | C31: =B31/$B$4
A32: Reward-point value | B32: =COUNTA(Catalogue!F2:F296) | C32: =B32/$B$4
A33: Monthly/quarterly/annual caps | B33: =COUNTA(Catalogue!G2:G296) | C33: =B33/$B$4
A34: Minimum transaction | B34: =COUNTA(Catalogue!H2:H296) | C34: =B34/$B$4
A35: Excluded categories/MCCs | B35: =COUNTA(Catalogue!I2:I296) | C35: =B35/$B$4
A36: Excluded merchants | B36: =COUNTA(Catalogue!J2:J296) | C36: =B36/$B$4
A37: Joining fee | B37: =COUNTA(Catalogue!K2:K296) | C37: =B37/$B$4
A38: Annual fee | B38: =COUNTA(Catalogue!L2:L296) | C38: =B38/$B$4
A39: Fee-waiver condition | B39: =COUNTA(Catalogue!M2:M296) | C39: =B39/$B$4
A40: Forex markup | B40: =COUNTA(Catalogue!N2:N296) | C40: =B40/$B$4
A41: Lounge benefits | B41: =COUNTA(Catalogue!O2:O296) | C41: =B41/$B$4
A42: Milestone benefits | B42: =COUNTA(Catalogue!P2:P296) | C42: =B42/$B$4
A43: Fuel surcharge waiver | B43: =COUNTA(Catalogue!Q2:Q296) | C43: =B43/$B$4
A44: Other benefits | B44: =COUNTA(Catalogue!R2:R296) | C44: =B44/$B$4
A45: Official source URL | B45: =COUNTA(Catalogue!S2:S296) | C45: =B45/$B$4
A46: Effective date | B46: =COUNTA(Catalogue!T2:T296) | C46: =B46/$B$4

Sheet Sources
A1: Issuer | B1: Source | C1: Date / status | D1: Official URL | E1: Data / claims used
A2: HDFC Bank | B2: Credit Cards catalogue | C2: Current | D2: https://www.hdfc.bank.in/credit-cards | E2: Card catalogue and card-specific product navigation
A3: ICICI Bank | B3: Credit Cards catalogue | C3: Current | D3: https://www.icicibank.com/personal-banking/cards/credit-card | E3: Current cards and product pages
A4: Axis Bank | B4: Schedule of Charges / KFS | C4: Current | D4: https://www.axisbank.com/docs/default-source/default-document-library/sosc-credit-cards.pdf | E4: Fees, fuel-waiver and transaction-charge rules across card variants
A5: Axis Bank | B5: Cashback Credit Card T&C | C5: Current | D5: https://www.axisbank.com/docs/default-source/ld/axis-bank-cashback-credit-card-tnc.pdf | E5: Cashback earn, caps, exclusions and fee-waiver terms
A6: SBI Card | B6: Credit Cards catalogue | C6: Current | D6: https://www.sbicard.com/en/personal/sbi-credit-card.page | E6: Current card features
A7: SBI Card | B7: Most Important Terms & Conditions | C7: Current | D7: https://www.sbicard.com/en/most-important-terms-and-conditions.page | E7: Issuer fees, charges and card-level conditions
A8: Kotak Mahindra Bank | B8: Credit Cards catalogue | C8: Current | D8: https://www.kotak.bank.in/en/personal-banking/cards/credit-cards.html | E8: Current cards, fees and headline benefits
A9: IDFC FIRST Bank | B9: Credit Cards catalogue | C9: Current | D9: https://www.idfcfirstbank.com/credit-card | E9: Current card comparison and product features
A10: IDFC FIRST Bank | B10: MITC / Fees and Charges | C10: Current | D10: https://www.idfcfirstbank.com/credit-card/fees-and-charges | E10: Joining/annual fees, forex, surcharge and other card terms
A11: IndusInd Bank | B11: Credit Cards catalogue | C11: Current/legacy | D11: https://www.indusind.bank.in/in/en/personal/cards/credit-card.html | E11: Current and retained legacy card feature material
A12: AU Small Finance Bank | B12: Credit Cards catalogue | C12: Current | D12: https://www.au.bank.in/personal-banking/credit-cards | E12: Current cards and product benefits
... A25: Federal Bank | B25: Credit Cards KFS / General Terms | C25: Current | D25: https://www.federalbank.co.in/-/credit-cards-general-terms-and-conditions-1 | E25: Current fees and forex markup for Federal Bank variants
A27: Second-pass reward/cashback sources
A28: Card | B28: Issuer | C28: Reward source type | D28: Reward source URL | E28: Research note
A29: IndianOil HDFC Bank Credit Card | B29: HDFC Bank | C29: Official issuer | D29: https://www.hdfc.bank.in/credit-cards/indianoil-hdfc-bank-credit-card | E29: Second-pass reward/cashback research; populated only from located source material.
A30: Tata Neu Infinity HDFC Bank Credit Card | B30: HDFC Bank | C30: Official issuer | D30: https://www.hdfc.bank.in/credit-cards/tata-neu-infinity-hdfc-bank-credit-card | E30: Second-pass reward/cashback research; populated only from located source material.
A31: HDFC Bank Freedom Credit Card | B31: HDFC Bank | C31: Official issuer | D31: https://www.hdfc.bank.in/credit-cards/freedom-credit-card | E31: Second-pass reward/cashback research; populated only from located source material.
A32: PhonePe HDFC Bank Uno Credit Card | B32: HDFC Bank | C32: Official issuer | D32: https://www.hdfc.bank.in/credit-cards/phonepe-hdfc-bank-uno-credit-card | E32: Second-pass reward/cashback research; populated only from located source material.
A33: PhonePe HDFC Bank Ultimo Credit Card | B33: HDFC Bank | C33: Official issuer | D33: https://www.hdfc.bank.in/credit-cards/phonepe-hdfc-bank-ultimo-credit-card | E33: Second-pass reward/cashback research; populated only from located source material.
A34: HDFC Bank Diners Club Black Metal Edition Credit Card | B34: HDFC Bank | C34: Official issuer | D34: https://v.hdfc.bank.in/htdocs/amp/personal/pay/cards/credit-cards/diners-club-black-metal-edition.html | E34: Second-pass reward/cashback research; populated only from located source material.
A35: HDFC Bank PIXEL Play Credit Card | B35: HDFC Bank | C35: Official issuer | D35: https://www.hdfc.bank.in/content/dam/hdfcbankpws/in/en/personal-banking/discover-products/cards/credit-cards/pixel-play-credit-card/terms-and-conditions-pixel-play-credit-card-16122025.pdf | E35: Second-pass reward/cashback research; populated only from located source material.
A36: HDFC Bank PIXEL Go Credit Card | B36: HDFC Bank | C36: Official issuer | D36: https://www.hdfc.bank.in/credit-cards/pixel-go-credit-card | E36: Second-pass reward/cashback research; populated only from located source material.
A37: HDFC Bank UPI RuPay Credit Card | B37: HDFC Bank | C37: Official issuer | D37: https://www.hdfc.bank.in/credit-cards/hdfc-bank-upi-rupay-credit-card | E37: Second-pass reward/cashback research; populated only from located source material.
A38: HDFC Bank Regalia Gold Credit Card | B38: HDFC Bank | C38: Official issuer | D38: https://www.hdfc.bank.in/blogs/regalia-gold-credit-card/redeem-regalia-gold-credit-card-reward-points | E38: Second-pass reward/cashback research; populated only from located source material.
A39: Tata Neu Plus HDFC Bank Credit Card | B39: HDFC Bank | C39: Official issuer | D39: https://www.hdfc.bank.in/credit-cards/tata-neu-plus-hdfc-bank-credit-card | E39: Second-pass reward/cashback research; populated only from located source material.
... A239: Scapia Federal Bank Credit Card | B239: Federal Bank | C239: Official issuer / co-brand | D239: https://www.federal.bank.in/documents/d/guest/cardholder_agreement-v11-30_04_26 | E239: Second-pass reward/cashback research; populated only from located source material.

Sheet Reward Research
A1: Reward / cashback second-pass research
A2: Research date | B2: 2026-09-09
A3: Original rows with both Base reward and Accelerated rewards blank | B3: 211
A4: Rows with at least one reward/cashback field recovered | B4: 211
A5: Rows with both base and accelerated fields populated | B5: 171
A6: Rows using a source labelled credible secondary | B6: 7
A7: Rows with intentionally descriptive/non-numeric reward wording | B7: 12
A9: Issuer | B9: Target rows | C9: Recovered at least one | D9: Credible-secondary rows
A10: AU Small Finance Bank | B10: 23 | C10: 23 | D10: 3
A11: American Express India | B11: 1 | C11: 1 | D11: 0
A12: Axis Bank | B12: 38 | C12: 38 | D12: 2
A13: BOBCARD | B13: 11 | C13: 11 | D13: 0
A14: Federal Bank | B14: 1 | C14: 1 | D14: 0
A15: HDFC Bank | B15: 17 | C15: 17 | D15: 0
A16: HSBC India | B16: 1 | C16: 1 | D16: 0
A17: ICICI Bank | B17: 17 | C17: 17 | D17: 0
A18: IDFC FIRST Bank | B18: 8 | C18: 8 | D18: 0
A19: IndusInd Bank | B19: 13 | C19: 13 | D19: 0
A20: Kotak Mahindra Bank | B20: 6 | C20: 6 | D20: 0
A21: RBL Bank | B21: 37 | C21: 37 | D21: 1
... A24: YES BANK | B24: 16 | C24: 16 | D24: 1
